<mujoco model="balljoint">
    <compiler angle="radian"/>
    <contact>
        <exclude body1="base_link" body2="link0"/>
    </contact>

    <worldbody>
        <body name="hand" pos="0 0 0" mocap="true">
            <geom name="hand" type="box" size=".02 .04 .06" rgba="0 .9 0 .5" contype="2" conaffinity="2"/>
        </body>

        <body name="target" pos="0 0 0" mocap="true">
            <geom name="target" type="sphere" size=".1 .2" rgba=".9 0 0 .5" contype="4" conaffinity="4"/>
        </body>

        <body name="base_link" pos="0 0 0">
            <geom name="base_link0" type="capsule" size=".1 .3" pos="0 0 0" rgba=".7 .7 .7 1" euler="1.57 0 0"/>
            <geom name="base_link1" type="capsule" size=".1 .3" pos="0 0 0" rgba=".7 .7 .7 1" euler="0 1.57 0"/>

            <body name="link0" pos="0 0 0">
                <joint name='joint0' type="ball" pos="0 0 0"/>
                <geom type="capsule" pos="0 0 .5" size=".1 .5" euler="0 0 0" rgba=".7 .7 .7 .5"/>

                <body name="EE" pos="0 0 1"/>
            </body>
        </body>
    </worldbody>

    <actuator>
        <motor name="joint0_motor0" joint="joint0" gear="1 0 0 0 0 0"/>
        <motor name="joint0_motor1" joint="joint0" gear="0 1 0 0 0 0"/>
        <motor name="joint0_motor2" joint="joint0" gear="0 0 1 0 0 0"/>
    </actuator>
</mujoco>

