<!-- Download stl files from -->
<!-- https://github.com/Kinovarobotics/kinova-ros/kinova_description/meshes -->
<!-- and place them in a meshes folder in this directory -->
<mujoco model="jaco2_gripper">
    <compiler angle="radian" meshdir="meshes" balanceinertia="true"/>

    <default>
        <light castshadow="false" diffuse="1 1 1" />
        <camera fovy="60" />
        <geom contype="1" conaffinity="1" />
    </default>

    <custom>
        <numeric name="START_ANGLES" data="2.0 3.14 1.57 4.71 0.0 3.04"/>
    </custom>

    <asset>
        <!-- arm models -->
        <mesh file="base.STL" />
        <mesh file="shoulder.STL"/>
        <mesh file="arm.STL"/>
        <mesh file="forearm.STL"/>
        <mesh file="wrist.STL"/>
        <mesh file="hand_3finger.STL"/>
        <mesh file="ring_big.STL"/>
        <mesh file="ring_small.STL"/>
        <mesh file="finger_distal.STL"/>
        <mesh file="finger_proximal.STL"/>
        <!-- keyboard keys -->
        <mesh file="alt.stl" />
        <mesh file="l-arrow-double.stl" />
        <mesh file="r-arrow-double.stl" />
        <mesh file="u-arrow-double.stl" />
        <mesh file="d-arrow-double.stl" />
        <mesh file="shift.stl" />
        <mesh file="enter.stl" />
        <mesh file="tab.stl" />
        <mesh file="esc.stl" />
        <mesh file="space.stl" />
        <mesh file="F1.stl" />
        <mesh file="F2.stl" />
        <mesh file="F3.stl" />
        <mesh file="F5.stl" />
        <mesh file="w.stl" />
        <mesh file="a.stl" />
        <mesh file="s.stl" />
        <mesh file="d.stl" />
        <!-- xbox keys -->
        <mesh file="xbox_button_blank_oversized.stl"/>
        <mesh file="xbox_x.stl"/>
        <mesh file="xbox_a.stl"/>
        <mesh file="xbox_b.stl"/>
        <mesh file="xbox_y.stl"/>
        <mesh file="xbox_start.stl"/>
        <mesh file="xbox_select.stl"/>
        <mesh file="xbox_home.stl"/>
        <mesh file="joystick_tilt.stl"/>
        <mesh file="joystick_arrow.stl"/>
        <mesh file="joystick_arrow_flat.stl"/>
        <mesh file="joystick_base.stl"/>
        <mesh file="dpad.stl"/>
        <mesh file="dpad_oversize.stl"/>
        <mesh file="controller_RB.stl"/>
        <mesh file="rb.stl"/>
        <mesh file="controller_LB.stl"/>
        <mesh file="lb.stl"/>
        <mesh file="controller_RT.stl"/>
        <mesh file="rt.stl"/>
        <mesh file="controller_LT.stl"/>
        <mesh file="lt.stl"/>
        <!-- world objects -->
        <mesh file="octagon.stl"/>
        <mesh file="adapt.stl" scale="0.5 0.5 0.5"/>
        <mesh file="brain.stl"/>
        <mesh file="weight.stl" scale="3 3 3"/>
        <mesh file="ISS.stl" scale="0.1 0.1 0.1"/>
        <mesh file="1lb.stl" scale="3 3 3"/>
        <mesh file="2_5lb.stl" scale="3 3 3"/>
        <mesh file="5lb.stl" scale="3 3 3"/>
        <mesh file="gravity.stl" scale="3 3 3"/>
        <mesh file="0_00N.stl" scale="3 3 3"/>
        <mesh file="1_62N.stl" scale="3 3 3"/>
        <mesh file="9_81N.stl" scale="3 3 3"/>
        <mesh file="3_71N.stl" scale="3 3 3"/>
        <mesh file="24_92N.stl" scale="3 3 3"/>

        <!-- <texture name="mars_terrain" file="meshes/mars_terrain.png" width="2000" height="2000" type="2d"/> -->
        <!-- <material name="mars_terrain" texture="mars_terrain" specular="0" shininess="0" reflectance="0" emission="1" /> -->
        <!--  -->
        <!-- <textureme="earth_terrain" file="meshes/earth_terrain.png" width="2000" height="2000" type="2d"/> -->
        <!-- <material name="earth_terrain" texture="earth_terrain" specular="0" shininess="0" reflectance="0" emission="1" /> -->
        <!--  -->
        <!-- <texture name="moon_terrain" file="meshes/moon_terrain.png" width="1200" height="1200" type="2d"/> -->
        <!-- <material name="moon_terrain" texture="moon_terrain" specular="0" shininess="0" reflectance="0" emission="1" /> -->
        <!--  -->
        <!-- <texture name="jupiter_terrain" file="meshes/jupiter_terrain.png" width="2000" height="2000" type="2d"/> -->
        <!-- <material name="jupiter_terrain" texture="jupiter_terrain" specular="0" shininess="0" reflectance="0" emission="1" /> -->

        <texture name="floor_tile" file="meshes/floor_tile.png" width="3000" height="3000" type="2d"/>
        <material name="tile" texture="floor_tile" specular="0" shininess="0" reflectance="0" emission="1" />

        <!-- <texture name="asteroid" file="meshes/asteroid.png" width="2000" height="2000" type="cube"/> -->
        <!-- <material name="asteroid" texture="asteroid" specular="0" shininess="0" reflectance="0" emission="1" /> -->

        <material name="blue_steel" specular="1" shininess="1" reflectance="1" rgba="0.1 0.125 0.15 1" emission="1" />

        <material name="carbon" specular="1" shininess="1" reflectance="1" rgba="0.05 0.05 0.05 1" emission="1" />

        <!-- <texture name="abr_word" file="meshes/abr_word&#45;cube.png" width="3620" height="3620" type="cube"/> -->
        <!--  -->
        <texture name="abr_word" file="meshes/abr_word_transparent.png" width="3620" height="2060" type="2d"/>
        <material name="abr_word" texture="abr_word" specular="0" shininess="0" reflectance="0" emission="1" />

        <texture name="exit" file="meshes/exit.png" width="1600" height="1000" type="2d"/>
        <material name="exit" texture="exit" specular="0" shininess="0" reflectance="0" emission="1" />

        <texture name="restart" file="meshes/restart.png" width="1600" height="1000" type="2d"/>
        <material name="restart" texture="restart" specular="0" shininess="0" reflectance="0" emission="1" />

        <texture name="demo_mode" file="meshes/demo_mode.png" width="1600" height="1000" type="2d"/>
        <material name="demo_mode" texture="demo_mode" specular="0" shininess="0" reflectance="0" emission="1" />

        <texture name="info" file="meshes/info.png" width="512" height="512" type="2d"/>
        <material name="info" texture="info" specular="0" shininess="0" reflectance="0" emission="1" />

        <!-- <texture name="black_rubber" file="meshes/black_rubber.png" width="3000" height="2250" type="2d"/> -->
        <!--  -->
        <texture name="black_rubber" file="meshes/black_rubber-cube.png" width="2250" height="2250" type="cube"/>
        <material name="black_rubber" texture="black_rubber" specular="0.5" shininess="0" reflectance="0" emission="1" />

        <texture name="black_rubber_2d" file="meshes/black_rubber.png" width="3000" height="2250" type="2d"/>
        <material name="black_rubber_2d" texture="black_rubber_2d" specular="0.5" shininess="0" reflectance="0" emission="1" />

        <texture name="scratched_aluminum" file="meshes/scratched_aluminum-cube.png" width="975" height="975" type="2d"/>

        <!-- <texture name="scratched_aluminum" file="meshes/scratched_aluminum3&#45;cube.png" width="3744" height="3744" type="2d"/> -->
        <!--  -->
        <material name="scratched_aluminum" texture="scratched_aluminum" />

        <!-- <texture name="blue_plastic" file="meshes/blue_plastic&#45;cube.png" width="2250" height="2250" type="cube"/> -->
        <!-- <material name="blue_plastic" texture="blue_plastic" /> -->

        <material name="grey_plastic" specular="0.5" shininess="0" reflectance="0" rgba="0.12 0.14 0.14 1" emission="1" />

        <material name="xbox_grey_1" specular="0" shininess="0" reflectance="0" rgba="0.62 0.64 0.64 1" emission="0" />
        <material name="xbox_grey_2" specular="0" shininess="0" reflectance="0" rgba="0.22 0.24 0.24 1" emission="0" />
        <material name="xbox_highlight_dark" specular="0" shininess="0" reflectance="0" rgba="1 0 0 1" emission="0" />
        <material name="xbox_highlight_light" specular="0" shininess="0" reflectance="0" rgba="1 1 0 0.9" emission="0" />

        <material name="key_col" specular="0.5" shininess="0" reflectance="0" rgba="1 1 0 0.9" emission="1" />

        <texture name="abr_logo" file="meshes/abr_logo.png" width="193" height="193" type="2d"/>
        <material name="logo" texture="abr_logo"/>

        <texture name="abr_logo_flip" file="meshes/abr_logo.png" width="193" height="193" type="2d" hflip="true"/>
        <material name="logo_flip" texture="abr_logo_flip"/>

        <texture name="foam_blocks" file="meshes/foam_blocks.png" width="2744" height="2744" type="2d"/>
        <material name="foam" texture="foam_blocks" specular="0" shininess="0" reflectance="0" emission="1" />

        <texture name="knurled_texture" file="meshes/grip.png" width="600" height="600" type="cube"/>
        <material name="knurled" texture="knurled_texture" specular="0" shininess="0" reflectance="0" emission="1" />

        <texture name="mars" file="meshes/mars_crop.png" width="882" height="882" type="2d"/>
        <material name="mars_surface" texture="mars" specular="0" shininess="0" reflectance="0" emission="1" />

        <texture name="jupiter" file="meshes/jupiter_crop.png" width="2048" height="2048" type="2d"/>
        <material name="jupiter_surface" texture="jupiter" specular="0" shininess="0" reflectance="0" emission="1" />

        <texture name="moon" file="meshes/moon_crop.png" width="2048" height="2048" type="2d"/>
        <material name="moon_surface" texture="moon" specular="0" shininess="0" reflectance="0" emission="1" />

        <texture name="earth" file="meshes/earth3x4.png" width="2048" height="1536" gridlayout=".U..LFRB.D.." gridsize="3 4"/>
        <material name="earth_surface" texture="earth" specular="0" shininess="0" reflectance="0" emission="1" />

        <texture name="stars" file="meshes/stars3x4.png" width="2048" height="2048" type="skybox" gridlayout=".U..LFRB.D.." gridsize="3 4"/>

    </asset>

    <contact>
        <exclude body1="dumbbell" body2="path_planner_orientation"/>
        <exclude body1="dumbbell" body2="path_planner"/>
        <exclude body1="dumbbell" body2="target_orientation"/>
        <exclude body1="dumbbell" body2="target"/>
        <exclude body1="dumbbell" body2="EE"/>
        <exclude body1="dumbbell" body2="adapt"/>
        <exclude body1="dumbbell" body2="brain"/>
    </contact>

    <worldbody>
        <!-- planet terrains -->
        <!-- <body name="earth_floor" mocap="true"> -->
        <!--     <geom name="earth_floor" pos="0 0 0.0" size="1 0.01" type="cylinder" material="earth_terrain"/> -->
        <!-- </body> -->
        <!--  -->
        <!-- <body name="mars_floor" mocap="true"> -->
        <!--     <geom name="mars_floor" pos="0 0 0.0" size="1 0.01" type="cylinder" material="mars_terrain"/> -->
        <!-- </body> -->
        <!--  -->
        <!-- <body name="moon_floor" mocap="true"> -->
        <!--     <geom name="moon_floor" pos="0 0 0.0" size="1 0.01" type="cylinder" material="moon_terrain"/> -->
        <!-- </body> -->
        <!--  -->
        <!-- <body name="jupiter_floor" mocap="true"> -->
        <!--     <geom name="jupiter_floor" pos="0 0 0.0" size="1 0.01" type="cylinder" material="jupiter_terrain"/> -->
        <!-- </body> -->
        <!--  -->
        <!-- <body name="ISS_floor" mocap="true"> -->
        <!--     <geom name="ISS_floor" pos="0 0 0.0" size="1 0.01" type="cylinder" material="tile"/> -->
        <!-- </body> -->
        <!-- <geom name="floor_asteroid" pos="0 0 &#45;0.02" size="1 0.01" type="cylinder" material="asteroid"/> -->
        <!--  -->
        <geom name="floor_foam_block" pos="0 0 0" size="0.5 0.5 0.05" type="plane" rgba="1 0.83 0.61 1" material="foam"/>
        <geom name="floor_grey_tile" pos="0 0 -0.001" size="0.75 0.75 0.05" type="plane" material="tile"/>

        <!-- control visualizations -->
        <body name="hand" pos="0 -0.5 0.5" mocap="true">
            <geom type="box" size=".002 .004 .006" rgba="0 .9 0 .5" contype="4" conaffinity="4"/>
        </body>

        <body name="target" pos="0 -0.5 0.5" mocap="true">
            <geom name="target" type="sphere" size="0.05" rgba=".9 0 0 .5" contype="2" conaffinity="2"/>
        </body>

        <body name="target_orientation" pos="0 -0.5 0.5" mocap="true">
            <geom type="box" size=".02 .04 .06" rgba=".9 0 0 .5" contype="4" conaffinity="4"/>
        </body>

        <body name="path_planner" pos="0 -0.5 0.5" mocap="true">
            <geom type="sphere" size="0.05" rgba="0 1 1 0.5" contype="8" conaffinity="8"/>
        </body>

        <body name="path_planner_orientation" pos="0 -0.5 0.5" mocap="true">
            <geom type="box" size=".02 .04 .06" rgba="0 1 1 .5" contype="2"/>
        </body>

        <body name="obstacle" pos="0 -0.5 0.5" mocap="true">
            <geom type="sphere" size="0.05" rgba="0 0 1 1"/>
        </body>

        <body name="elbow" pos="0 -0.5 0.5" mocap="true">
            <geom name="elbow" type="sphere" size="0.05" rgba="0 1 1 .25" contype="32" conaffinity="32"/>
        </body>

        <light directional="true" pos="-0.5 0.5 3" dir="0 0 -1" />

        <!-- interactable objects -->
        <body name="dumbbell_stand1" pos="-0.39 0 0.015">
            <geom name="dumbbell_stand1" type="box" size="0.05 0.075 0.015" friction="1 0.005 0.0001" solimp="0.95 0.95 0.01" solref="0.01 1" condim="4" material='knurled'/>
        </body>
        <body name="dumbbell_stand2" pos="-0.61 0 0.015">
            <geom name="dumbbell_stand2" type="box" size="0.05 0.075 0.015" friction="1 0.005 0.0001" solimp="0.95 0.95 0.01" solref="0.01 1" condim="4" material='knurled'/>
        </body>

        <body name="dumbbell" pos="-0.5 0 0.085">
            <geom name="handle" type="cylinder" pos="0 0 0" material="knurled" size="0.0127 0.06" euler="0 1.57 0" friction="1 0.5 0.01" solimp="0.95 0.95 0.01 0.5 6" solref="0.01 1" condim="6" margin="0.0"/>
            <geom name="mass1" type="mesh" mesh="octagon" pos="0.1 0 0" material="black_rubber" friction="1 0.005 0.001" solimp="0.95 0.95 0.01" solref="0.01 1" condim="6" />
            <geom name="mass2" type="mesh" mesh="octagon" pos="-0.1 0 0" material="black_rubber" friction="1 0.005 0.001" solimp="0.95 0.95 0.01" solref="0.01 1" condim="6" />
            <inertial pos="0 0 0" mass="4" diaginertia="0.1 0.1 0.1"/>
            <freejoint name="dumbbell"/>
        </body>

        <!-- icons and visualizations -->
        <body name="main_logo" mocap="true">
            <geom type="box" pos='0 0 0' size="0.16 0.1 .0001" material='abr_word' contype="32" conaffinity='32' euler='1.57 0 0'/>
        </body>

        <body name="exit" mocap="true">
            <geom type="box" pos='0 0 0' size="0.16 0.1 .0001" material='exit' contype="32" conaffinity='32'/>
        </body>

        <body name="restart" mocap="true">
            <geom type="box" pos='0 0 0' size="0.16 0.1 .0001" material='restart' contype="32" conaffinity='32'/>
        </body>

        <body name="demo_mode" mocap="true">
            <geom type="box" pos='0 0 0' size="0.16 0.1 .0001" material='demo_mode' contype="32" conaffinity='32'/>
        </body>

        <body name="info" mocap="true">
            <geom type="cylinder" pos='0 0 0' size="0.05 0.01" material='info' contype="32" conaffinity='32'/>
        </body>

        <!-- <body name="flag" mocap="true"> -->
        <!--     <geom type='mesh' mesh='flag3' pos='0.5 &#45;0.5 0' material='abr_word'/> -->
        <!--     <geom type="box" pos='&#45;0.585 0.75 0.5' size="0.16 0.1 .0001" material='abr_word' contype="2" euler='1.57 0 0'/> -->
        <!--     <geom name="pole" type="cylinder" pos="&#45;0.75 0.75 0.32" material="knurled" size="0.005 0.3"/> -->
        <!--     <geom name="pole_top" type="sphere" pos="&#45;0.75 0.75 0.62" material="knurled" size="0.01"/> -->
        <!-- </body> -->

        <!-- <body name="abr_word_logo" mocap="true"> -->
        <!--     <geom type="box" pos='0 &#45;0.625 0.0' size="0.16 0.1 .0001" material='abr_word' contype="2"/> -->
        <!--         <!&#45;&#45; euler='1.57 0 0'/> &#45;&#45;> -->
        <!--         <!&#45;&#45;  &#45;&#45;> -->
        <!-- </body> -->

        <body name="adapt" pos="0 -0.5 0.5" mocap="true">
            <geom name="adapt" type="mesh" mesh="adapt" rgba="0.5 0.5 0.5 0.1" material='knurled' contype="32" conaffinity="32"/>
        </body>

        <body name="1lb" pos="0 -0.5 0.5" mocap="true">
            <geom name="1lb" type="mesh" mesh="1lb" rgba="0.77 0.79 0.81 1" contype="32" conaffinity="32"/>
        </body>

        <body name="2_5lb" pos="0 -0.5 0.5" mocap="true">
            <geom name="2_5lb" type="mesh" mesh="2_5lb" rgba="0.77 0.79 0.81 1" contype="32" conaffinity="32"/>
        </body>

        <body name="5lb" pos="0 -0.5 0.5" mocap="true">
            <geom name="5lb" type="mesh" mesh="5lb" rgba="0.77 0.79 0.81 1" contype="32" conaffinity="32"/>
        </body>

        <body name="weight" pos="0 -0.5 0.5" mocap="true">
            <geom name="weight" type="mesh" mesh="weight" rgba="0.77 0.79 0.81 1" contype="32" conaffinity="32"/>
        </body>

        <body name="gravity" pos="0 -0.5 0.5" mocap="true">
            <geom name="gravity" type="mesh" mesh="gravity" rgba="0.77 0.79 0.81 1" contype="32" conaffinity="32"/>
        </body>

        <body name="0_00N" pos="0 -0.5 0.5" mocap="true">
            <geom name="0_00N" type="mesh" mesh="0_00N" rgba="0.77 0.79 0.81 1" contype="32" conaffinity="32"/>
        </body>

        <body name="1_62N" pos="0 -0.5 0.5" mocap="true">
            <geom name="1_62N" type="mesh" mesh="1_62N" rgba="0.77 0.79 0.81 1" contype="32" conaffinity="32"/>
        </body>

        <body name="9_81N" pos="0 -0.5 0.5" mocap="true">
            <geom name="9_81N" type="mesh" mesh="9_81N" rgba="0.77 0.79 0.81 1" contype="32" conaffinity="32"/>
        </body>

        <body name="3_71N" pos="0 -0.5 0.5" mocap="true">
            <geom name="3_71N" type="mesh" mesh="3_71N" rgba="0.77 0.79 0.81 1" contype="32" conaffinity="32"/>
        </body>

        <body name="24_92N" pos="0 -0.5 0.5" mocap="true">
            <geom name="24_92N" type="mesh" mesh="24_92N" rgba="0.77 0.79 0.81 1" contype="32" conaffinity="32"/>
        </body>

        <body name="brain" pos="0 -0.5 0.5" mocap="true">
            <geom type="mesh" mesh="brain" rgba="0.92 0.82 0.84 1"/>
        </body>

        <!-- Keyboard keys -->
        <body name="l-arrow-double" pos="0 -0.5 0.5" mocap="true">
            <geom type="mesh" mesh="l-arrow-double" euler="1.57 0 0" contype="32" conaffinity="32" material='grey_plastic'/>
            <geom  name='l_arrow_col' type='box' size="0.02 0.02 0.01495" contype="32" conaffinity="32" material="key_col"/>
        </body>

        <body name="r-arrow-double" pos="0 -0.5 0.5" mocap="true">
            <geom type="mesh" mesh="r-arrow-double" euler="1.57 0 0" contype="32" conaffinity="32" material='grey_plastic'/>
            <geom  name='r_arrow_col' type='box' size="0.02 0.02 0.01495" contype="32" conaffinity="32" material="key_col"/>
        </body>

        <body name="u-arrow-double" pos="0 -0.5 0.5" mocap="true">
            <geom type="mesh" mesh="u-arrow-double" euler="1.57 0 0" contype="32" conaffinity="32" material='grey_plastic'/>
            <geom  name='u_arrow_col' type='box' size="0.02 0.02 0.01495" contype="32" conaffinity="32" material="key_col"/>
        </body>

        <body name="d-arrow-double" pos="0 -0.5 0.5" mocap="true">
            <geom type="mesh" mesh="d-arrow-double" euler="1.57 0 0" contype="32" conaffinity="32" material='grey_plastic'/>
            <geom  name='d_arrow_col' type='box' size="0.02 0.02 0.01495" contype="32" conaffinity="32" material="key_col"/>
        </body>

        <body name="alt1" pos="0 -0.5 0.5" mocap="true">
            <geom type="mesh" euler="0 3.14 0" mesh="alt" contype="32" conaffinity="32" material='grey_plastic'/>
            <geom  name='alt1_arrow_col' type='box' size="0.02 0.0145 0.02" contype="32" conaffinity="32" material="key_col"/>
        </body>

        <body name="u-arrow-double2" pos="0 -0.5 0.5" mocap="true">
            <geom type="mesh" mesh="u-arrow-double" contype="32" conaffinity="32" material='grey_plastic'/>
            <geom  name='u2_arrow_col' type='box' size="0.02 0.01495 0.02" contype="32" conaffinity="32" material="key_col"/>
        </body>

        <body name="alt2" pos="0 -0.5 0.5" mocap="true">
            <geom type="mesh" euler="0 3.14 0" mesh="alt" contype="32" conaffinity="32" material='grey_plastic'/>
            <geom  name='alt2_arrow_col' type='box' size="0.02 0.0145 0.02" contype="32" conaffinity="32" material="key_col"/>
        </body>

        <body name="d-arrow-double2" pos="0 -0.5 0.5" mocap="true">
            <geom type="mesh" mesh="d-arrow-double" contype="32" conaffinity="32" material='grey_plastic'/>
            <geom  name='d2_arrow_col' type='box' size="0.02 0.01495 0.02" contype="32" conaffinity="32" material="key_col"/>
        </body>

        <body name="w" pos="0 -0.5 0.5" mocap="true" euler="1.57 0 0">
            <geom type="mesh" mesh="w" contype="32" conaffinity="32" material='grey_plastic'/>
            <geom  name='w_col' type='box' size="0.02 0.02 0.0145" contype="32" conaffinity="32" material="key_col"/>
        </body>

        <body name="a" pos="0 -0.5 0.5" mocap="true" euler="1.57 0 0">
            <geom type="mesh" mesh="a" contype="32" conaffinity="32" material='grey_plastic'/>
            <geom  name='a_col' type='box' size="0.02 0.02 0.0145" contype="32" conaffinity="32" material="key_col"/>
        </body>

        <body name="s" pos="0 -0.5 0.5" mocap="true" euler="1.57 0 0">
            <geom type="mesh" mesh="s" contype="32" conaffinity="32" material='grey_plastic'/>
            <geom  name='s_col' type='box' size="0.02 0.02 0.0145" contype="32" conaffinity="32" material="key_col"/>
        </body>

        <body name="d" pos="0 -0.5 0.5" mocap="true" euler="1.57 0 0">
            <geom type="mesh" mesh="d" contype="32" conaffinity="32" material='grey_plastic'/>
            <geom  name='d_col' type='box' size="0.02 0.02 0.0145" contype="32" conaffinity="32" material="key_col"/>
        </body>

        <body name="shift" pos="0 -0.5 0.5" mocap="true">
            <geom type="mesh" mesh="shift" contype="32" conaffinity="32" material='grey_plastic'/>
            <geom  name='shift_col' type='box' size="0.04 0.0145 0.02" contype="32" conaffinity="32" material="key_col"/>
        </body>

        <body name="enter" pos="0 -0.5 0.5" mocap="true">
            <geom type="mesh" mesh="enter" contype="32" conaffinity="32" material='grey_plastic'/>
            <geom  name='enter_col' type='box' size="0.04 0.0145 0.02" contype="32" conaffinity="32" material="key_col"/>
        </body>

        <body name="space" pos="0 -0.5 0.5" mocap="true" euler='1.57 0 0'>
            <geom type="mesh" mesh="space" contype="32" conaffinity="32" material='grey_plastic'/>
            <geom  name="space_col" type='box' size="0.07 0.02 0.0145" contype="32" conaffinity="32" material="key_col"/>
        </body>

        <body name="F1" pos="0 -0.5 0.5" mocap="true" euler="1.57 0 0">
            <geom type="mesh" mesh="F1" contype="32" conaffinity="32" material='grey_plastic'/>
            <geom  name='F1_col' type='box' size="0.02 0.02 0.0149" contype="32" conaffinity="32" material="key_col"/>
        </body>

        <body name="F2" pos="0 -0.5 0.5" mocap="true" euler="1.57 0 0">
            <geom type="mesh" mesh="F2" contype="32" conaffinity="32" material='grey_plastic'/>
            <geom  name='F2_col' type='box' size="0.02 0.02 0.0149" contype="32" conaffinity="32" material="key_col"/>
        </body>

        <body name="F3" pos="0 -0.5 0.5" mocap="true">
            <geom type="mesh" mesh="F3" contype="32" conaffinity="32" material='grey_plastic'/>
            <geom  name='F3_col' type='box' size="0.02 0.02 0.0149" contype="32" conaffinity="32" material="key_col"/>
        </body>

        <body name="F5" pos="0 -0.5 0.5" mocap="true" euler='1.57 0 0'>
            <geom type="mesh" mesh="F5" contype="32" conaffinity="32" material='grey_plastic'/>
            <geom  name='F5_col' type='box' size="0.02 0.02 0.0149" contype="32" conaffinity="32" material="key_col"/>
        </body>

        <body name="tab" pos="0 -0.5 0.5" mocap="true" euler="1.57 0 0">
            <geom type="mesh" mesh="tab" contype="32" conaffinity="32" material='grey_plastic'/>
            <geom  name='tab_col' type='box' size="0.03 0.02 0.0145" contype="32" conaffinity="32" material="key_col"/>
        </body>

        <body name="esc" pos="0 -0.5 0.5" mocap="true" euler="1.57 0 0">
            <geom type="mesh" mesh="esc" contype="32" conaffinity="32" material='grey_plastic'/>
            <geom  name='esc_col' type='box' size="0.03 0.02 0.0145" contype="32" conaffinity="32" material="key_col"/>
        </body>


        <!-- Xbox buttons -->
        <body name="xbox_x" pos="0 -0.5 0.5" mocap="true" euler='1.3 0 0'>
            <geom type="mesh" mesh="xbox_button_blank_oversized" contype="32" conaffinity="32" material='xbox_grey_1'/>
            <geom type="mesh" mesh="xbox_x" contype="32" conaffinity="32" rgba='0.13 0.65 0.9 1'/>
        </body>

        <body name="xbox_a" pos="0.2 -0.5 0.5" mocap="true" euler='1.3 0 0'>
            <geom type="mesh" mesh="xbox_button_blank_oversized" contype="32" conaffinity="32" material='xbox_grey_1'/>
            <geom type="mesh" mesh="xbox_a" contype="32" conaffinity="32" rgba='0 0.8 0 0.9'/>
        </body>

        <body name="xbox_y" pos="0.4 -0.5 0.5" mocap="true" euler='1.3 0 0'>
            <geom type="mesh" mesh="xbox_button_blank_oversized" contype="32" conaffinity="32" material='xbox_grey_1'/>
            <geom type="mesh" mesh="xbox_y" contype="32" conaffinity="32" rgba='1 1 0 0.9'/>
        </body>

        <body name="xbox_b" pos="0.6 -0.5 0.5" mocap="true" euler='1.3 0 0'>
            <geom type="mesh" mesh="xbox_button_blank_oversized" contype="32" conaffinity="32" material='xbox_grey_1'/>
            <geom type="mesh" mesh="xbox_b" contype="32" conaffinity="32" rgba='1 0 0 0.9'/>
        </body>

        <body name="xbox_home" pos="0.6 -0.5 0.5" mocap="true" euler='1.3 0 0'>
            <geom type="mesh" mesh="xbox_button_blank_oversized" contype="32" conaffinity="32" material='xbox_grey_1'/>
            <geom type="mesh" mesh="xbox_home" contype="32" conaffinity="32" rgba='0 1 0 1'/>
        </body>

        <body name="xbox_start" pos="0.6 -0.5 0.5" mocap="true" euler='1.3 0 0'>
            <geom type="mesh" mesh="xbox_button_blank_oversized" contype="32" conaffinity="32" material='xbox_grey_1'/>
            <geom type="mesh" mesh="xbox_start" contype="32" conaffinity="32" material='xbox_highlight_light'/>
        </body>

        <body name="xbox_select" pos="0.6 -0.5 0.5" mocap="true" euler='1.3 0 0'>
            <geom type="mesh" mesh="xbox_button_blank_oversized" contype="32" conaffinity="32" material='xbox_grey_1'/>
            <geom type="mesh" mesh="xbox_select" contype="32" conaffinity="32" material='xbox_highlight_light'/>
        </body>

        <body name="r_dpad" pos="0.6 -0.5 0.5" mocap="true" euler='1.3 0 0'>
            <geom type="mesh" mesh="dpad" contype="32" conaffinity="32" material='xbox_grey_1'/>
            <geom type="mesh" mesh="dpad_oversize" contype="32" conaffinity="32" material="xbox_highlight_light"/>
        </body>

        <body name="l_dpad" pos="0.6 -0.5 0.5" mocap="true" euler='1.3 0 3.14'>
            <geom type="mesh" mesh="dpad" contype="32" conaffinity="32" material='xbox_grey_1'/>
            <geom type="mesh" mesh="dpad_oversize" contype="32" conaffinity="32" material="xbox_highlight_light"/>
        </body>

        <body name="u_dpad" pos="0.6 -0.5 0.5" mocap="true" euler='1.3 0 1.57'>
            <geom type="mesh" mesh="dpad" contype="32" conaffinity="32" material='xbox_grey_1'/>
            <geom type="mesh" mesh="dpad_oversize" contype="32" conaffinity="32" material="xbox_highlight_light"/>
        </body>

        <body name="d_dpad" pos="0.6 -0.5 0.5" mocap="true" euler='1.3 0 4.71'>
            <geom type="mesh" mesh="dpad" contype="32" conaffinity="32" material='xbox_grey_1'/>
            <geom type="mesh" mesh="dpad_oversize" contype="32" conaffinity="32" material="xbox_highlight_light"/>
        </body>

        <body name="r_joystick" pos="0.6 -0.5 0.5" mocap="true" euler='0 0 0'>
            <geom type="mesh" mesh="joystick_tilt" contype="32" conaffinity="32" material='xbox_grey_2'/>
            <geom type="mesh" mesh="joystick_base" contype="32" conaffinity="32" material='grey_plastic'/>
            <geom type="mesh" mesh="joystick_arrow" contype="32" conaffinity="32" material="xbox_highlight_light"/>
        </body>

        <body name="l_joystick" pos="0.6 -0.5 0.5" mocap="true" euler='0 0 3.14'>
            <geom type="mesh" mesh="joystick_tilt" contype="32" conaffinity="32" material='xbox_grey_2'/>
            <geom type="mesh" mesh="joystick_base" contype="32" conaffinity="32" material='grey_plastic'/>
            <geom type="mesh" mesh="joystick_arrow" contype="32" conaffinity="32" material="xbox_highlight_light"/>
        </body>

        <body name="u_joystick1" pos="0.6 -0.5 0.5" mocap="true" euler='0 0 1.57'>
            <geom type="mesh" mesh="joystick_tilt" contype="32" conaffinity="32" material='xbox_grey_2'/>
            <geom type="mesh" mesh="joystick_base" contype="32" conaffinity="32" material='grey_plastic'/>
            <geom type="mesh" mesh="joystick_arrow_flat" contype="32" conaffinity="32" material="xbox_highlight_light"/>
        </body>

        <body name="u_joystick2" pos="0.6 -0.5 0.5" mocap="true" euler='0 0 1.57'>
            <geom type="mesh" mesh="joystick_tilt" contype="32" conaffinity="32" material='xbox_grey_2'/>
            <geom type="mesh" mesh="joystick_base" contype="32" conaffinity="32" material='grey_plastic'/>
            <geom type="mesh" mesh="joystick_arrow_flat" contype="32" conaffinity="32" material="xbox_highlight_light"/>
        </body>

        <body name="d_joystick1" pos="0.6 -0.5 0.5" mocap="true" euler='0 0 4.71'>
            <geom type="mesh" mesh="joystick_tilt" contype="32" conaffinity="32" material='xbox_grey_2'/>
            <geom type="mesh" mesh="joystick_base" contype="32" conaffinity="32" material='grey_plastic'/>
            <geom type="mesh" mesh="joystick_arrow_flat" contype="32" conaffinity="32" material="xbox_highlight_light"/>
        </body>

        <body name="d_joystick2" pos="0.6 -0.5 0.5" mocap="true" euler='0 0 4.71'>
            <geom type="mesh" mesh="joystick_tilt" contype="32" conaffinity="32" material='xbox_grey_2'/>
            <geom type="mesh" mesh="joystick_base" contype="32" conaffinity="32" material='grey_plastic'/>
            <geom type="mesh" mesh="joystick_arrow_flat" contype="32" conaffinity="32" material="xbox_highlight_light"/>
        </body>

        <body name="r_bumper" pos="0.0 -0.5 0.5" mocap="true" euler='2.2 0 0'>
            <geom type="mesh" mesh="controller_RB" contype="32" conaffinity="32" rgba='1 1 1 1'/>
            <geom type="mesh" mesh="rb" contype="32" conaffinity="32" material='xbox_highlight_dark'/>
        </body>

        <body name="l_bumper" pos="0.9 -0.5 0.5" mocap="true" euler='2.2 0 0'>
            <geom type="mesh" mesh="controller_LB" contype="32" conaffinity="32" rgba='1 1 1 1'/>
            <geom type="mesh" mesh="lb" contype="32" conaffinity="32" material='xbox_highlight_dark'/>
        </body>

        <body name="r_trigger1" pos="0.6 -0.5 0.5" mocap="true" euler='2.2 0 0'>
            <geom type="mesh" mesh="controller_RT" contype="32" conaffinity="32" rgba='1 1 1 1'/>
            <geom type="mesh" mesh="rt" contype="32" conaffinity="32" material='xbox_highlight_dark'/>
        </body>

        <body name="r_trigger2" pos="0.6 -0.5 0.5" mocap="true" euler='2.2 0 0'>
            <geom type="mesh" mesh="controller_RT" contype="32" conaffinity="32" rgba='1 1 1 1'/>
            <geom type="mesh" mesh="rt" contype="32" conaffinity="32" material='xbox_highlight_dark'/>
        </body>

        <!-- Set up for left trigger, currently unused -->
        <!-- <body name="l_trigger" pos="0.3 &#45;0.5 0.5" mocap="true" euler='2.2 0 0'> -->
        <!--     <geom type="mesh" mesh="controller_LT" contype="32" conaffinity="32" rgba='1 1 1 1'/> -->
        <!--     <geom type="mesh" mesh="lt" contype="32" conaffinity="32" material='xbox_highlight_dark'/> -->
        <!-- </body> -->

        <!-- planets -->
        <body name="ISS" pos="0 -0.5 0.5" mocap="true">
            <geom name='ISS' type='mesh' mesh='ISS' pos='0 0 0' contype='32' conaffinity='32'/>
        </body>

        <body name="earth" pos="0 -0.5 0.5" mocap="true">
            <geom name="earth" type="sphere" size="0.24" material="earth_surface" euler="1.57 0 0"/>
        </body>

        <body name="moon" pos="0 -0.5 0.5" mocap="true">
            <geom name="moon" type="sphere" size="0.1" material="moon_surface" euler="1.57 0 0"/>
        </body>

        <body name="mars" pos="0 -0.5 0.5" mocap="true">
            <geom name="mars" type="sphere" size="0.2" material="mars_surface" euler="1.57 0 0"/>
        </body>

        <body name="jupiter" pos="0 -2 1.5" mocap="true">
            <geom name="jupiter" type="sphere" size="0.3" material="jupiter_surface" euler="1.57 0 0"/>
        </body>

        <body name="base_link" pos="0 0 0">
            <geom name="link0" type="mesh" mesh="base" pos="0 0 0" material="scratched_aluminum"/>
            <inertial pos="0.000000 0.000000 0.125500" mass="1.226" diaginertia="0.25 0.25 0.25"/>
            <geom type="sphere" size="0.025" pos="0.000000 0.000000 0.125500" rgba="1 0.5 0 1"/>

            <body name="link1" pos="0 0 0.157">
                <inertial pos="-0.000042 -0.001285 0.112784" mass="0.754000" diaginertia="0.3 0.3 0.3"/>
                <geom name="link1" type="mesh" mesh="shoulder" pos="0 0 0" euler="0 3.14 0" material="scratched_aluminum"/>
                <!-- <geom name="ring0" type="mesh" mesh="ring_big" material="black_rubber"/> -->
                <geom name="joint_logo0" type="cylinder" size="0.032 0.005" material="logo" pos="0 -0.0364 0.1186" euler="1.6 0 0"/>
                <joint name="joint0" axis="0 0 -1" pos="0 0 0"/>


                <body name="link2" pos="0 0.0016 0.1186">
                    <inertial pos="0.000014 0.009353 0.329006" mass="1.010000" diaginertia="0.3 0.3 0.3"/>
                    <geom name="link2" type="mesh" mesh="arm" pos="0 0 0" euler="1.57 0 3.14" material="scratched_aluminum"/>
                    <geom name="ring1" type="mesh" mesh="ring_big" material="black_rubber" euler="1.57 0 0"/>
                    <geom name="joint_logo1" type="cylinder" size="0.032 0.005" material="logo_flip" pos="0 0.038 0" euler="1.52 0 0"/>
                    <geom name="joint_logo2" type="cylinder" size="0.032 0.005" material="logo_flip" pos="0 0.0385 0.410" euler="1.62 0 0"/>
                    <joint name="joint1" pos="0 0 0" axis="0 -1 0"  ref="3.14" limited="true" range="0.872665 5.41052"/>

                    <body name="link3" pos="0 0 0.410">
                        <inertial pos="-0.000039 -0.018069 0.153270" mass="0.559000" diaginertia="0.275 0.275 0.275"/>
                        <geom name="link3" type="mesh" mesh="forearm" pos="0 0 0" euler="1.57 3.14 0" material="scratched_aluminum"/>
                        <joint name="joint2" pos="0 0 0" axis="0 1 0" ref="3.14" limited="true" range="0.331613 5.95157"/>
                        <geom name="joint_logo3" type="cylinder" size="0.032 0.005" material="logo" pos="0 -0.038 0" euler="1.54 0 0"/>

                        <body name="ring2">
                            <geom name="ring2" type="mesh" mesh="ring_big" material="black_rubber" euler="1.57 0 0" contype="16" conaffinity="16"/>
                        </body>

                        <body name="link4" pos="0 -0.0115 0.2072">
                            <inertial pos="0.000000 0.032302 0.059705" mass="0.417000" diaginertia="0.175 0.175 0.175"/>
                            <geom name="link4" type="mesh" mesh="wrist" euler="3.14 0 0" material="scratched_aluminum"/>
                            <geom name="ring3" type="mesh" mesh="ring_small" material="black_rubber"/>
                            <joint name="joint3" pos="0 0 0" axis="0 0 -1" ref="0"/>

                            <body name="link5" pos="0 0.037 0.0641">
                                <inertial pos="-0.000000 0.035545 0.057833" mass="0.417" diaginertia="0.175 0.175 0.175"/>
                                <geom name="link5" type="mesh" mesh="wrist" euler="-1.0472 3.14 0" material="scratched_aluminum"/>
                                <geom name="ring4" type="mesh" mesh="ring_small" material="black_rubber" euler="-1.0471 0 0"/>
                                <joint name="joint4" pos="0 0 0" axis="0 -1.9 -1.1" ref="0"/>

                                <body name="link6" pos="0 0.037 0.0641">
                                    <inertial pos="0.000030 -0.006840 0.082220" mass="0.727000" diaginertia="0.025 0.025 0.025"/>
                                    <geom name="link6" type="mesh" mesh="hand_3finger" euler="3.14 0 0" material="scratched_aluminum" solimp="0.97 0.97 0.01" solref="0.01 1" condim="6" />
                                    <geom name="ring5" type="mesh" mesh="ring_small" material="black_rubber"/>
                                    <joint name="joint5" pos="0 0 0" axis="0 0 -1" ref="0"/>

                                    <!-- for fingertip EE -->
                                    <!-- <body name="EE" pos="0 0 0.20222" euler="0 0 0"> -->
                                    <!-- </body> -->

                                    <!-- for palm EE -->
                                    <body name="EE" pos="0 0 0.12" euler="0 0 0">
                                    </body>

                                    <body name="thumb_proximal" pos="0.002786 -0.03126 0.114668" quat="0.95922726  0.262085    0.02762996 -0.10213274">
                                        <geom name="thumb_proximal" type="mesh" mesh="finger_proximal" euler="0 -1.5707 0" friction="1 0.5 0.01" solimp="0.95 0.95 0.01 0.5 6" solref="0.01 1" condim="6" margin="0.0"/>
                                        <joint name="joint_thumb" pos="0 0 0" axis="1 0 0" ref="1.1" limited="true" range="-0.2 1.1" solimplimit="0.95 0.95 0.01" solreflimit="0.01 1" stiffness="5" springref="0.0" damping="0.35"/>

                                        <body name="thumb_distal" pos="0 -0.003 0.044">
                                            <geom name="thumb_distal" type="mesh" mesh="finger_distal" euler="0 -1.5707 0" friction="1 0.5 0.01" solimp="0.95 0.95 0.01 0.5 6" solref="0.01 1" condim="6" margin="0.0"/>
                                            <joint name="joint_thumb_distal" pos="0 0 0" axis="-1 0 0" ref="0" limited="true" range="-0.4 0.4" stiffness="5" springref="-0.4" damping="0.5" solimplimit="0.95 0.95 0.01" solreflimit="0.01 1"/>
                                        </body>
                                    </body>

                                    <body name="index_proximal" pos="0.022256 0.027073 0.114668" quat="0.96181018 -0.25771638 0.0238668 -0.08907205">
                                        <geom name="index_proximal" type="mesh" mesh="finger_proximal" quat="5.63312174e-04  7.06824957e-01 -5.62863772e-04  7.07388045e-01" friction="1 0.5 0.01" solimp="0.95 0.95 0.01 0.5 6" solref="0.01 1" condim="6" margin="0.0"/>
                                        <joint name="joint_index" pos="0 0 0" axis="-1 0 0" ref="1.1" limited="true" range="-0.2 1.1" solimplimit="0.95 0.95 0.01" solreflimit="0.01 1" stiffness="5" springref="0.0" damping="0.35"/>

                                        <body name="index_distal" pos="0 0.003 0.044">
                                            <geom name="index_distal" type="mesh" mesh="finger_distal" quat="5.63312174e-04  7.06824957e-01 -5.62863772e-04  7.07388045e-01" friction="1 0.5 0.01" solimp="0.95 0.95 0.01 0.5 6" solref="0.01 1" condim="6" margin="0.0"/>
                                            <joint name="joint_index_distal" pos="0 0 0" axis="1 0 0" ref="0" limited="true" range="-0.4 0.4" stiffness="5" springref="-0.4" damping="0.5" solimplimit="0.95 0.95 0.01" solreflimit="0.01 1"/>
                                        </body>
                                    </body>

                                    <body name="pinky_proximal" pos="-0.022256 0.027073 0.114816" quat="0.96181018 -0.25771638 -0.0238668 0.08907205">
                                        <geom name="pinky_proximal" type="mesh" mesh="finger_proximal" quat="5.63312174e-04  7.06824957e-01 -5.62863772e-04  7.07388045e-01" friction="1 0.5 0.01" solimp="0.95 0.95 0.01 0.5 6" solref="0.01 1" condim="6" margin="0.0"/>
                                        <joint name="joint_pinky" pos="0 0 0" axis="-1 0 0" ref="1.1" limited="true" range="-0.2 1.1" solimplimit="0.95 0.95 0.01" solreflimit="0.01 1" stiffness="5" springref="0.0" damping="0.35"/>

                                        <body name="pinky_distal" pos="0 0.003 0.044">
                                            <geom name="pinky_distal" type="mesh" mesh="finger_distal" quat="5.63312174e-04  7.06824957e-01 -5.62863772e-04  7.07388045e-01" friction="1 0.5 0.01" solimp="0.95 0.95 0.01 0.5 6" solref="0.01 1" condim="6" margin="0.0"/>
                                            <joint name="joint_pinky_distal" pos="0 0 0" axis="1 0 0" ref="0" limited="true" range="-0.4 0.4" stiffness="5" springref="0.4" damping="0.5" solimplimit="0.95 0.95 0.01" solreflimit="0.01 1"/>
                                        </body>
                                    </body>
                                </body>
                            </body>
                        </body>
                    </body>
                </body>
            </body>
        </body>

    </worldbody>

    <actuator>
        <motor name="joint0_motor" joint="joint0"/>
        <motor name="joint1_motor" joint="joint1"/>
        <motor name="joint2_motor" joint="joint2"/>
        <motor name="joint3_motor" joint="joint3"/>
        <motor name="joint4_motor" joint="joint4"/>
        <motor name="joint5_motor" joint="joint5"/>
        <motor name="joint_thumb_motor" joint="joint_thumb"/>
        <motor name="joint_index_motor" joint="joint_index"/>
        <motor name="joint_pinky_motor" joint="joint_pinky"/>
        <!-- <motor name="joint_thumb_motor_distal" joint="joint_thumb_distal"/> -->
        <!-- <motor name="joint_index_motor_distal" joint="joint_index_distal"/> -->
        <!-- <motor name="joint_pinky_motor_distal" joint="joint_pinky_distal"/> -->
    </actuator>

</mujoco>
