<!-- NOTE: the joint limits and references have not been set. If using -->
<!-- this to control a real ur5, make sure they align with the values -->
<!-- used in the real arm firmware -->
<mujoco model="ur5">
    <compiler angle="radian" meshdir="meshes" balanceinertia="true"/>

    <default>
        <light castshadow="false" diffuse="1 1 1" />
        <camera fovy="60" />
        <geom contype="1" conaffinity="1" />
    </default>

    <custom>
        <numeric name="START_ANGLES" data="0 0 0 0 0 0" />
        <numeric name="N_GRIPPER_JOINTS" data="0" />
        <text name="google_id" data="1SjWRUl-D1FZ5fB2cy4jF4X9wTsQ5LWzo"/>
    </custom>

    <asset>
        <!-- arm models -->
        <mesh file="link0.stl" />
        <mesh file="link1.stl" />
        <mesh file="link1_cap.stl" />
        <mesh file="link1_connector.stl" />
        <mesh file="link2.stl" />
        <mesh file="link2_tube.stl" />
        <mesh file="link2_cap.stl" />
        <mesh file="link2_connector.stl" />
        <mesh file="link3a.stl" />
        <mesh file="link3a_connector.stl" />
        <mesh file="link3_tube.stl" />
        <mesh file="link3_cap.stl" />
        <mesh file="link3b.stl" />
        <mesh file="link3b_connector.stl" />
        <mesh file="link3b_connector2.stl"/>
        <mesh file="link4.stl" />
        <mesh file="link4_cap.stl" />
        <mesh file="link4_connector.stl" />
        <mesh file="link5.stl" />
        <mesh file="link5_cap.stl" />
        <mesh file="link5_connector.stl" />
        <mesh file="link6.stl" />
        <mesh file="link6_connector.stl" />

        <texture name="floor_tile" file="meshes/floor_tile.png" width="3000" height="3000" type="2d"/>
        <material name="tile" texture="floor_tile" specular="0" shininess="0" reflectance="0" emission="1" />
        <material name="silver" specular="1" shininess="0.5" reflectance="1" emission="0.25" rgba="0.82 0.82 0.82 1"/>
        <material name="grey" specular="1" shininess="0.5" reflectance="1" emission="0.1" rgba="0.5 0.5 0.5 1"/>
        <material name="blue" specular="1" shininess="0.5" reflectance="1" emission="0" rgba="0.678 0.847 0.902 1"/>
        <material name="black" specular="1" shininess="0.5" reflectance="1" emission="0" rgba="0.2 0.2 0.2 1"/>
    </asset>

    <worldbody>
        <geom name="floor_grey_tile" pos="0 0 -0.001" size="0.75 0.75 0.05" type="plane" material="tile"/>

        <body name="hand" pos="0 0 -0.15" mocap="true">
            <geom type="box" size=".002 .004 .006" rgba="0 .9 0 .5" contype="2" conaffinity="2"/>
        </body>

        <body name="target" pos="0 0 -0.15" mocap="true">
            <geom name="target" type="sphere" size="0.05" rgba=".9 0 0 .5" contype="4" conaffinity="4"/>
        </body>

        <body name="target_orientation" pos="0 0 -0.15" mocap="true">
            <geom type="box" size=".02 .04 .06" rgba=".9 0 0 .5" contype="8" conaffinity="8"/>
        </body>

        <body name="path_planner" pos="0 0 -0.15" mocap="true">
            <geom type="sphere" size="0.05" rgba="0 1 1 0.5" contype="16" conaffinity="16"/>
        </body>

        <body name="path_planner_orientation" pos="0 0 -0.15" mocap="true">
            <geom type="box" size=".02 .04 .06" rgba="0 1 1 .5" contype="16" conaffinity="16"/>
        </body>

        <body name="obstacle" pos="0 0 -0.15" mocap="true">
            <geom type="sphere" size="0.05" rgba="0 0 1 1"/>
        </body>

        <light directional="true" pos="-0.5 0.5 3" dir="0 0 -1" />

        <body name="base_link" pos="0 0 0">
            <geom name="link0" type="mesh" mesh="link0" pos="0 0 0"/>

            <body name="link1" pos="0 0 0">
                <geom name="link1" type="mesh" mesh="link1" pos="0 0 0" material="grey"/>
                <geom name="link1_cap" type="mesh" mesh="link1_cap" pos="0 0 0" material="blue"/>
                <geom name="link1_connector" type="mesh" mesh="link1_connector" pos="0 0 0" material="black"
                    conaffinity="32" contype="32"/>
                <inertial pos="0.0 -0.02561 0.00193" mass="3.7" diaginertia="0.1 0.1 0.1"/>
                <joint name="joint0" axis="0 0 1" pos="0 0 0.0293"/>

                <body name="link2" pos="0 0 0">
                    <geom name="link2" type="mesh" mesh="link2" pos="0 0 0" material="grey"/>
                    <geom name="link2_tube" type="mesh" mesh="link2_tube" pos="0 0 0" material="silver"/>
                    <geom name="link2_cap" type="mesh" mesh="link2_cap" pos="0 0 0" material="blue"/>
                    <geom name="link2_connector" type="mesh" mesh="link2_connector" pos="0 0 0" material="black"
                        conaffinity="32" contype="32"/>
                    <inertial pos="0.2125 0.0 0.11336" mass="8.393" diaginertia="0.15 0.15 0.15"/>
                    <joint name="joint1" axis="-1 0 0" pos="-0.0743 0 0.0892"/>

                    <body name="link3" pos="0 0 0">
                        <geom name="link3a" type="mesh" mesh="link3a" pos="0 0 0" material="grey"/>
                        <geom name="link3a_connector" type="mesh" mesh="link3a_connector" pos="0 0 0" material="black"
                            conaffinity="32" contype="32"/>
                        <geom name="link3_tube" type="mesh" mesh="link3_tube" pos="0 0 0" material="silver"/>
                        <geom name="link3_cap" type="mesh" mesh="link3_cap" pos="0 0 0" material="blue"/>
                        <geom name="link3b" type="mesh" mesh="link3b" pos="0 0 0" material="grey"/>
                        <geom name="link3b_connector" type="mesh" mesh="link3b_connector" pos="0 0 0" material="black"/>
                        <geom name="link3b_connector2" type="mesh" mesh="link3b_connector2" pos="0 0 0" material="grey"
                            conaffinity="32" contype="32"/>
                        <inertial pos="0.15 0.0 0.0265" mass="2.33" diaginertia="0.1 0.1 0.1"/>
                        <joint name="joint2" axis="1 0 0" pos="-0.1743 0 0.5142"/>

                        <body name="link4" pos="0 0 0">
                            <inertial pos="0.0 -0.0018 0.01634" mass="1.219" diaginertia="0.1 0.1 0.1"/>
                            <joint name="joint3" axis="-1 0 0" pos="-0.0569 0 0.90645"/>
                            <geom name="link4" type="mesh" mesh="link4" pos="0 0 0" material="grey"/>
                            <geom name="link4_cap" type="mesh" mesh="link4_cap" pos="0 0 0" material="blue"/>
                            <geom name="link4_connector" type="mesh" mesh="link4_connector" pos="0 0 0" material="black"
                                conaffinity="32" contype="32"/>

                            <body name="link5" pos="0 0 0">
                                <inertial pos="0.0 -0.0018 0.01634" mass="1.219" diaginertia="0.1 0.1 0.1"/>
                                <joint name="joint4" axis="0 0 1" pos="-0.110 0 0.9595"/>
                                <geom name="link5" type="mesh" mesh="link5" pos="0 0 0" material="grey"/>
                                <geom name="link5_cap" type="mesh" mesh="link5_cap" pos="0 0 0" material="blue"/>
                                <geom name="link5_connector" type="mesh" mesh="link5_connector" pos="0 0 0" material="black"
                                    conaffinity="32" contype="32"/>

                                <body name="link6" pos="0 0 0">
                                    <inertial pos="0.0 0.0 -0.001159" mass="0.1879" diaginertia="0.1 0.1 0.1"/>
                                    <joint name="joint5" axis="-1 0 0" pos="-0.1595 0 1.0012"/>
                                    <geom name="link6" type="mesh" mesh="link6" pos="0 0 0" material="silver"/>
                                    <geom name="link6_connector" type="mesh" mesh="link6_connector" pos="0 0 0" material="black"
                                        conaffinity="32" contype="32"/>

                                    <body name="EE" pos="-0.192 0 1.0012" euler="0 0 0"/>
                                </body>
                            </body>
                        </body>
                    </body>
                </body>
            </body>
        </body>
    </worldbody>

    <actuator>
        <motor name="joint0_motor" joint="joint0"/>
        <motor name="joint1_motor" joint="joint1"/>
        <motor name="joint2_motor" joint="joint2"/>
        <motor name="joint3_motor" joint="joint3"/>
        <motor name="joint4_motor" joint="joint4"/>
        <motor name="joint5_motor" joint="joint5"/>
    </actuator>

</mujoco>
